Workbook

Sheet Instructions
A1: Blind human audit — 805 inverse-discordant records
A2: Reviewer: Alberto Zambudio-Munuera | Version: 18 October 2026 | Complete independently before reconciliation
A4: Purpose and blinding
A5: This workbook contains every non-priority record in the inverse discordant pattern: Claude INCLUDE, Codex EXCLUDE, and Grok UNCERTAIN or EXCLUDE (n=805). Previous AI votes and rationales have been removed from view.
A6: Review all rows independently. Do not compare decisions with the other reviewer until both workbooks are complete. The row order was randomized with fixed seed 20261018 and is identical in both reviewer files.
A7: This is title/abstract screening. If eligibility cannot be ruled out from the available information, choose INCLUDE or UNCERTAIN; both trigger retrieval. A missing abstract is not, by itself, a reason to exclude.
A9: Include or retain for full text when
A10: Population: adults with suspected or confirmed prostate cancer, bladder or upper-tract urothelial carcinoma, renal mass, or kidney cancer.
A11: Intervention: AI, machine learning, deep learning, computer vision, natural-language processing, or an algorithmic prediction system contributes to a patient-level or clinical care-pathway task.
A12: Design: randomized comparison; prospective clinical evaluation; prospective or contemporaneous implementation; or a prespecified locked-model evaluation using material from a completed randomized trial.
A13: Outcomes: clinical performance, decisions, workflow, implementation, safety, resources, patient experience, or patient outcomes. At screening, retain uncertainty rather than infer absence.
A15: Exclude only when clearly ineligible
... A21: Enter reviewer_decision, primary_reason when excluded, notes when helpful, and review_date. The Action column is calculated automatically. The control sheet must show 805 reviewed and zero missing exclusion reasons before reconciliation.

Sheet Screening
A1: Blind screening decisions — inverse discordant pattern (n=805)
A2: Yellow columns are reviewer inputs. INCLUDE and UNCERTAIN both advance to retrieval.
A3: audit_order | B3: record_id | C3: year | D3: title | E3: abstract | F3: journal | G3: record_type | H3: abstract_available | I3: reviewer_decision | J3: primary_reason | K3: notes | L3: review_date | M3: action
A4: 1 | B4: LIB-05440 | C4: 2024 | D4: 18F-DCFPyL PET/MRI Radiomics for Intraprostatic Prostate Cancer Detection and Metastases Prediction Using Whole-Gland Segmentation | E4: Introduction: To evaluate the diagnostic performance of combined 18F-DCFPyL PET/MRI whole-gland-derived radiomics for detecting clinically significant (cs) prostate cancer (PCa) (ISUP GG≥2) and predicting nodal and distant metastases in therapy-naïve patients. Methods: This ethics review board-approved, retrospective analysis of two prospective clinical trials included 103 treatment-naïve men who had confirmed or suspected PCa. Recruited patients had either suspicion of PCa and negative systematic biopsies or clinically discordant low-risk PCa (n=20), patients being considered for focal therapy (n=31) or patients with unfavourable intermediate or high-risk PCa (n=52). All patients were enrolled between 2017 and 2020 and underwent 18F-DCFPyL PET/MRI. Radiomic feature analysis of PET/MRI was obtained using commercial software via the quantitation of various radionics features based on the spatial arrangement and variation of pixel intensities within a defined volume of interest. Whole-prostate segmentations were performed on each modality separately. On the MRI, whole-gland T2-weighted sequence and whole-gland apparent diffusion coefficient (ADC) map were evaluated. PET volumes of interest (VOI) were defined based on (a) background threshold, (b) peak threshold, (c) threshold at 40%, and (d) threshold at 70% of the SUVmax. Since a thresholding method was not available for the MRI component (T2, ADC), the contours for the MRI-derived VOI were performed manually (by an expert specialist in prostate MRI) in a slice-by-slice fashion to cover the entire prostate. The radiomics features, including overall 307 different features, were extracted from the segmented volumes in accordance with the image biomarker standardization initiative (IBSI) guidelines. The reference standard for suspicious prostatic lesions was histopathology (prostate biopsy) in all patients. The highest reported ISUP GG was taken into account for each prostate gland. For nodal and distant metastatic assessment, a composite standard of reference was applied for all lesions identified on conventional imaging (CT and bone scan ± mpMRI) or PET and included histopathology, correlative imaging, and clinical/biochemical follow-up. Univariate logistic regression was done to evaluate potential predictors across all calculated features. A predictive modelling approach using multivariable logistic regression with internal cross-validation was performed to calculate estimates and evaluate model performance. Results: A total of 103 patients (mean age=65; mean PSA=23.4) were evaluated. csPCa was confirmed in 89 (86%) patients, four patients had ISUP GG1, and 10 patients were negative for malignancy. Multiple models were built to predict the whole-gland ISUP GG, including clinical (Age and PSA), T2w (MRI-only; including only NGLDM Busyness), 18F-DCFPyL PET (PET-only; including only NGLDM Busyness), clinical+T2w, clinical+PET, T2w+PET (hybrid), and clinical+T2w+PET (full model). The imaging-based hybrid model (T2w+PET) provided the highest AUC (0.89) for the prediction of csPCa. No statistically significant PET or MRI radiomic feature was found for N-stage prediction. For M staging, the T2w whole-gland radiomic was found to be the best predictive model (AUC=0.94). Conclusions: Hybrid PET/MRI radiomics (whole-gland T2w+PET) was the best-performing model to predict csPCA, outperforming the clinical model. This indicates a complementary value of the hybrid PET/MRI model for noninvasive csPCa detection. Additionally, T2w whole-gland radiomics was able to predict distant metastases in this cohort. | F4: J. Nucl. Med. | G4: JOUR; Conference Abstract | H4: YES | I4: EXCLUDE | J4: Ineligible publication type | K4: CONFERENCE_ABSTRACT | L4: 46313 | M4: =IF(OR(I4="INCLUDE",I4="UNCERTAIN"),"RETRIEVE",IF(I4="EXCLUDE","EXCLUDE",""))
A5: 2 | B5: LIB-03469 | C5: 2026 | D5: Artificial-intelligence models vs. radiologists in the detection of clinically significant prostate cancer on mpMRI: a meta-analysis. | E5: OBJECTIVE: Multiparametric magnetic resonance imaging (mpMRI) detects clinically significant prostate cancer (csPCa, Gleason Grade Group ≥ 2) with high sensitivity but limited specificity and inter-reader variability. Artificial intelligence (AI), particularly convolutional neural networks (CNNs) and deep learning, may improve diagnostic consistency and accuracy. This meta-analysis compares AI systems and experienced radiologists in detecting csPCa using mpMRI. METHODS: We performed a systematic review and meta-analysis of English-language non-RCT studies. PubMed, Embase, and Cochrane databases were searched up to May 2025, yielding 855 studies. Only studies comparing CNN-based or deep-learning AI models to radiologists were included. Pooled sensitivity, specificity, diagnostic odds ratio (DOR), and area under the receiver operating curve (AUC) were calculated using a bivariate random-effects model. RESULTS: Ten studies with 2586 patients were analyzed. AI systems showed pooled sensitivity of 0.90 (95% CI 0.84-0.94) and specificity of 0.69 (95% CI 0.45-0.85). Radiologists had a sensitivity of 0.89 (95% CI 0.82-0.94) and a specificity of 0.60 (95% CI 0.43-0.75). DOR was 17.54 (95% CI 9.34-32.94) for AI and 12.35 (95% CI 4.96-30.76) for radiologists. Summary receiver operating characteristic (SROC) curves indicated similar diagnostic accuracy, with AI slightly outperforming radiologists (AUC 0.88 vs. 0.85). CONCLUSION: AI systems perform comparably to radiologists in detecting csPCa on mpMRI, with a potential edge in specificity, though confidence intervals overlapped. High heterogeneity and the retrospective nature of all included studies limit reliability, necessitating prospective validation. AI could serve as an adjunct in prostate cancer diagnosis, potentially improving precision and reducing unnecessary biopsies with further model refinement. KEY POINTS: Question Interpretation of mpMRI for clinically significant prostate cancer varies among radiologists, affecting diagnostic consistency. Findings Meta-analysis shows AI has comparable sensitivity and potentially superior specificity to radiologists in detecting significant prostate cancer on mpMRI, though confidence intervals overlapped. Clinical relevance AI has the potential to enhance diagnostic accuracy, reduce unnecessary biopsies, and improve consistency in prostate cancer detection, thereby supporting more reliable and standardized imaging assessments across centers. | F5: European radiology | G5: Journal Article; Meta-Analysis; Systematic Review; Comparative Study | H5: YES | I5: EXCLUDE | J5: Ineligible publication type | K5: NON_PRIMARY_PUBLICATION | L5: 46313 | M5: =IF(OR(I5="INCLUDE",I5="UNCERTAIN"),"RETRIEVE",IF(I5="EXCLUDE","EXCLUDE",""))
A6: 3 | B6: LIB-06805 | C6: 2019 | D6: Serial T2-Weighted Magnetic Resonance Images Acquired on a 1.5 Tesla Magnetic Resonance Linear Accelerator Reveal Radiomic Feature Variation in Organs at Risk: An Exploratory Analysis of Novel Metrics of Tissue Response in Prostate Cancer. | E6: "Delta-radiomics" investigates variations in quantitative image metrics over time and can yield important clinical information. We hypothesized that in patients undergoing active radiation therapy (RT) for prostate cancer (PCa), there would exist observable variation in the quantitative metrics that describe the T2-weighted (T2W) intensity histogram in the prostate and surrounding organs at risk (OAR) over time. We investigated the feasibility of acquisition and subsequent analysis of the delta-radiomic profiles of these regions of interest (ROI) in serial T2W magnetic resonance (MR) images obtained on a 1.5 Tesla (T) Magnetic Resonance Linear Accelerator (MRL). Principally, we sought to illustrate the significance of longitudinal radiomic data acquisition for tissue response monitoring and provide a framework for future hypothesis driven research. Patients with PCa undergoing treatment with RT were compiled from an ongoing prospective observational imaging trial using a 1.5 T MRL (NCT30500081). Contiguous axial slices of prostate parenchyma were contoured and temporally normalized to sections of Sartorius muscle which served as a control. Similarly, contiguous sections of rectal and bladder wall adjacent to the prostate were contoured and temporally normalized to regions of these organs further removed from the planning target volume (PTV). First order statistical descriptors of the T2W intensity histogram were extracted and evaluated for changes over time using linear mixed effects regression modeling and post-hoc contrasts. Benjamini-Hochberg corrections were employed to reduce the effects of multiple testing and control for the false discovery rate (FDR). Four patients with a median age of 69 comprised this exploratory cohort. One patient had low-risk disease, two had intermediate (one favorable, one unfavorable), and one had high risk disease. Three out of four patients underwent definitive radiation to 75.6 Gray (Gy) in 42 fractions and one received hypofractionated therapy to a total dose of 70 Gy over 28 fractions, and all received treatment on a conventional linear accelerator. The most significant acute toxicity event was grade 2 GU dysfunction observed in two patients. Follow up ranged from 1 month to 10 months post treatment, and no long-term complications were reported in patients who completed treatment at least one month prior. Bladder wall adjacent to the prostate demonstrated significant variation in the mean and median metric values after the first week of treatment. In addition, rectal wall adjacent to the prostate exhibited significant variation in the mean, median, and standard deviation metric values by the second week of treatment. No significant variation in any radiomic feature was observed in the Sartorius control. This exploratory study is one of the earliest examining the delta-radiomic characteristics of the T2W intensity histogram in OAR extracted from images acquired on a 1.5 T MRL in patients actively being treated with RT for PCa. We demonstrated a feasible approach to longitudinal radiomic data acquisition providing limitless opportunity for future research. Analysis of the delta-radiomic profiles in OAR revealed significant variation in metrics after only one week of RT in bladder and rectal wall adjacent to the prostate. These findings must be further investigated and validated with expanded data sets with long-term follow up and correlation to clinical outcomes including toxicity and tumor control. | F6: Cureus | G6: Journal Article | H6: YES | I6: EXCLUDE | J6: No eligible AI/ML system | K6: NO_RELEVANT_AI | L6: 46313 | M6: =IF(OR(I6="INCLUDE",I6="UNCERTAIN"),"RETRIEVE",IF(I6="EXCLUDE","EXCLUDE",""))
A7: 4 | B7: LIB-05517 | C7: 2025 | D7: Comparative outcomes and prognosis in patients with ureteral upper tract urothelial carcinoma undergoing segmental ureterectomy versus radical nephroureterectomy: a multicenter cohort study. | E7: BACKGROUND: Although radical nephroureterectomy (RNU) with bladder cuff excision remains the gold standard treatment for upper tract urothelial carcinoma (UTUC), segmental ureterectomy (SU) may offer a nephron-sparing alternative. Studies comparing oncologic outcomes and renal functional outcomes between SU and RNU have yielded controversial, often conflicting results. Furthermore, investigations specifically involving ureteral UTUC patients in northern China are scarce. METHODS: We retrospectively enrolled 546 ureteral urothelial carcinoma patients (282 SU and 264 RNU cases) from three hospitals between October 2003 and September 2024 to assess overall survival (OS) and intravesical recurrence-free survival (IV-RFS) as oncologic outcomes, and to evaluate renal functional outcomes (preoperative, postoperative [2-month] and delta change in estimated glomerular filtration rate [eGFR] and serum creatinine [Scr]). The prognostic impact of surgical approach and clinicopathological variables were evaluated using Kaplan-Meier analysis with log-rank tests and Cox regression models. Significant predictors were incorporated into a validated nomogram for personalized 3-, 4-, and 5-year OS and IV-RFS probability estimation. Furthermore, eight machine learning algorithms (Lasso Cox, random survival forest [RSF], CoxBoost, generalized boosted regression modeling [GBM], support vector machine [Survival-SVM], eXtreme Gradient Boosting [XGBoost], supervised principal components [SuperPC], and partial least squares regression for Cox [plsRcox]) were implemented for OS and IV-RFS prediction modeling. Finally, we quantitatively pooled our cohort data with literature evidence retrieved from major databases (PubMed, Cochrane, Embase, Web of Science) up to 21 May 2025, to compare survival and renal function outcomes between the two procedures using Stata 14.0. Subgroup assessments and leave-one-out sensitivity analyses were performed to address potential confounding factors related to heterogeneity. RESULTS: Firstly, the multicenter retrospective cohort study revealed that SU was associated with reduced IV-RFS and was identified as a significant independent predictor of IV-RFS (HR = 1.48; P = 0.02). Meanwhile, there was no significant difference in OS between SU and RNU. Algorithm comparison confirmed optimal discriminative performance for IV-RFS (3-year AUC: 0.771, 4-year: 0.758, 5-year: 0.761) and OS (3-year AUC: 0.739, 4-year: 0.726, 5-year: 0.710). Decision curve analysis demonstrated the excellent clinical applicability of the nomograms for OS and IV-RFS, which enhanced model precision and clinical utility. Furthermore, in the meta-analysis, 21 studies including 31 293 patients were selected for inclusion, spanning publication years from 2010 to 2025. Regarding survival outcomes, although no statistically significant differences were observed in OS risk ( P = 0.696), CSS risk ( P = 0.765), or RFS ( P = 0.072) between patients receiving SU and those undergoing RNU, SU was associated with lower IV-RFS compared to RNU (HR = 1.21, P = 0.019). Subgroup analysis stratified by geographic region revealed significantly reduced OS with SU versus RNU in European cohorts (HR = 1.24, P = 0.001). Concerning renal functional outcomes, the SU group demonstrated significantly higher postoperative eGFR (WMD, 14.16 mL/min; P < 0.001) and greater delta change in eGFR (WMD, 11.78 mL/min; P < 0.001). CONCLUSION: SU achieves cancer-specific and overall survival comparable to RNU, even in high-grade ureteral UTUC, while significantly improving postoperative renal function. However, it necessitates multidisciplinary management of intravesical recurrence risk. Validation of molecular predictors and prospective trials in advanced disease are essential to further expand and validate the therapeutic landscape of SU. | F7: International journal of surgery (London, England) | G7: Journal Article; Multicenter Study; Comparative Study | H7: YES | I7: EXCLUDE | J7: No eligible AI/ML system | K7: NO_RELEVANT_AI | L7: 46313 | M7: =IF(OR(I7="INCLUDE",I7="UNCERTAIN"),"RETRIEVE",IF(I7="EXCLUDE","EXCLUDE",""))
A8: 5 | B8: LIB-01411 | C8: 2023 | D8: The efficacy of red channel enhanced images for AI segmentation of bladder tumors in Cystoscopic | E8: Introduction & Objectives: Bladder tumors have high intravesical recurrence rate after transurethral resection of the bladder tumor (TURBT). Especially, overlooking and incompletely resecting tumors causes early intravesical recurrences. White light imaging (WLI) is the gold standard method, however it sometimes overlooked tumors about 10-20%. Although Narrow-band imaging and photodynamic diagnosis have improved the detection sensitivities, those accuracies are less objective and poor reproducible. Recently, artificial intelligence (AI) has been applying in diagnostic imaging. Segmentation is a commonly used AI method to present the shape of the object, and has possibility to correctly display the bladder tumors. In general, many cystoscpic images must be collected to create highly accurate AI; However, collecting the enormous images from only one institution is arduous task. To solve this problem, image processing has possibility to improve segmentation accuracies. In this study, we implemented image processing system that enhanced red color channel of cystoscopic images, and evaluated its efficacy in AI segmentation comparing to original cystoscopic images. Materials & Methods: We retrospectively collected cystoscopic images by converting TURBT videos, and divided those images into training and testing data. We constructed a segmentation system based on U-Net and implemented the image processing system to automatically create red channel enhanced image (RCEI). We conducted two AI training; one was the trained by only original cystoscopic images and another was the trained by only RCEI, and compared the two segmentation accuracies. As the evaluation metrics, we calculated IoU that represents the overlap area between the bladder tumors in the ground truth images and the AI segmentation maps. We also calculated pixel-wise sensitivity (PWSe), pixel-wise specificity (PWSp) and pixel-wise positive predictive value (PWPPV), representing the AI diagnostic accuracy per pixel. Results: We obtained 1,790 cystoscopic images from 120 patients. The T-stage of tumors are follows; 70, Ta; 22, T1; 21, T2; 9 carcinoma in situ, respectively. The IoU, PWSe, and PWPPV in RCEI were 77.0%, 88.0%, and 86.5%, which had improved 3.7%, 3.3%, and 1.3% of the AI trained by only original cystoscopic images, respectively. Conclusions: Our proposed image processing system could detect and display more bladder tumors compared with conventional cystoscopic images. Based on this system, we will try to create real time detecting-aid segmentation system. [Figure presented] | F8: Eur. Urol. | G8: JOUR; Conference Abstract | H8: YES | I8: EXCLUDE | J8: Ineligible publication type | K8: CONFERENCE_ABSTRACT | L8: 46313 | M8: =IF(OR(I8="INCLUDE",I8="UNCERTAIN"),"RETRIEVE",IF(I8="EXCLUDE","EXCLUDE",""))
A9: 6 | B9: LIB-00259 | C9: 2023 | D9: CONFIDENT-trial protocol: a pragmatic template for clinical implementation of artificial intelligence assistance in pathology. | E9: INTRODUCTION: Artificial intelligence (AI) has been on the rise in the field of pathology. Despite promising results in retrospective studies, and several CE-IVD certified algorithms on the market, prospective clinical implementation studies of AI have yet to be performed, to the best of our knowledge. In this trial, we will explore the benefits of an AI-assisted pathology workflow, while maintaining diagnostic safety standards. METHODS AND ANALYSIS: This is a Standard Protocol Items: Recommendations for Interventional Trials-Artificial Intelligence compliant single-centre, controlled clinical trial, in a fully digital academic pathology laboratory. We will prospectively include prostate cancer patients who undergo prostate needle biopsies (CONFIDENT-P) and breast cancer patients who undergo a sentinel node procedure (CONFIDENT-B) in the University Medical Centre Utrecht. For both the CONFIDENT-B and CONFIDENT-P trials, the specific pathology specimens will be pseudo-randomised to be assessed by a pathologist with or without AI assistance in a pragmatic (bi-)weekly sequential design. In the intervention group, pathologists will assess whole slide images (WSI) of the standard hematoxylin and eosin (H&E)-stained sections assisted by the output of the algorithm. In the control group, pathologists will assess H&E WSI according to the current clinical workflow. If no tumour cells are identified or when the pathologist is in doubt, immunohistochemistry (IHC) staining will be performed. At least 80 patients in the CONFIDENT-P and 180 patients in the CONFIDENT-B trial will need to be enrolled to detect superiority, allocated as 1:1. Primary endpoint for both trials is the number of saved resources of IHC staining procedures for detecting tumour cells, since this will clarify tangible cost savings that will support the business case for AI. ETHICS AND DISSEMINATION: The ethics committee (MREC NedMec) waived the need of official ethical approval, since participants are not subjected to procedures nor are they required to follow rules. Results of both trials (CONFIDENT-B and CONFIDENT-P) will be published in scientific peer-reviewed journals. | F9: BMJ open | G9: Journal Article; Research Support, Non-U.S. Gov't | H9: YES | I9: EXCLUDE | J9: Protocol/no results | K9: PROTOCOL_NO_RESULTS | L9: 46313 | M9: =IF(OR(I9="INCLUDE",I9="UNCERTAIN"),"RETRIEVE",IF(I9="EXCLUDE","EXCLUDE",""))
A10: 7 | B10: LIB-03896 | C10: 2026 | D10: Analysis of genomic and clinical predictors of overall survival and PSA response: Results from the PRECISION registry. | E10: Background: Outcomes in advanced prostate cancer vary substantially according to clinical and genomic characteristics among patients with metastatic castration-resistant prostate cancer (mCRPC). We sought to identify predictors of overall survival (OS) and prostate-specific antigen (PSA) response using data from the PRECISION real-world registry of mCRPC patients treated with poly(ADP-ribose) polymerase inhibitors (PARPi). Methods: Patient-level data from five centers (Dana Farber Cancer Institute, Thomas Jefferson University, University of British Colombia, University of Washington, Yale University) were aggregated, including demographics, clinical characteristics, genomic alterations, treatments, and clinical outcomes. OS was defined as the time from the first date of PARPi treatment to death or the last date the patient was known to be alive. PSA response was defined as a confirmed ≥50% decline from the PSA level measured closest to the start of PARPi treatment. Ten candidate variables per endpoint were selected via a random forest-based feature selection. Cox models stratified by study were used for OS, and logistic regression models with study included as an additional covariate were used for PSA response. Similarly, non-BRCA mutation status was defined as the presence of any observed mutation in genes other than BRCA, including ATM, CHEK2, MSH2, PALB2, BRIP1, and BARD1. Results: The combined dataset included n = 327 patients, with heterogeneity in baseline characteristics and treatments across studies. The prevalence of BRCA (BRCA1 or BRCA2) and non BRCA mutations was 39% and 37% respectively. Median OS for patients with BRCA mutations was 21 months (95% CI:16–28), compared with 15 months (95% CI: 14–18) for those without BRCA mutations. No difference in median OS was observed between patients with and without non-BRCA mutations: 16 months (95%CI: 14-22) and 17 months (15-21), respectively. Cox models identified age, N stage, PSMA–lutetium therapy, PARPi use within a clinical trial, prior taxane treatment (docetaxel or cabazitaxel), and BRCA as important predictors of OS. The corresponding hazard ratios with 95% confidence intervals are shown in the table below. Conclusions: These results from real-world data highlight the importance of incorporating genomic information and treatment-specific variables when predicting outcomes in advanced prostate cancer and demonstrate the utility of multi-study integrative analyses. (Table Presented.) | F10: ASCO MEETING ABSTRACTS | G10: JOUR; Conference Abstract | H10: YES | I10: EXCLUDE | J10: Ineligible publication type | K10: CONFERENCE_ABSTRACT | L10: 46313 | M10: =IF(OR(I10="INCLUDE",I10="UNCERTAIN"),"RETRIEVE",IF(I10="EXCLUDE","EXCLUDE",""))
A11: 8 | B11: LIB-04470 | C11: 2018 | D11: Machine learning-based lesion detection via quantitative high frequency ultrasound for prostate-cancer imaging using a novel high resolution micro-ultrasound platform | E11: INTRODUCTION AND OBJECTIVES: Currently, transrectal ultrasound (TRUS) guided biopsies is the only method for definitive diagnosis of prostate cancer. Studies by our group suggest that quantitative ultrasound (QUS) using machine learning-based lesion detection via high resolution micro-ultrasound could provide a more-sensitive, automated mechanism of identifying and targeting biopsies at cancersuspicious regions in the prostate. METHODS: Our previous studies utilized ultrasound signals at typical clinical frequencies, i.e., in the 6-MHz range. In our current study, a novel, 29-MHz, fine-resolution, micro-ultrasound instrument (ExactVuTM micro-ultrasound, Exact Imaging, Markham, Canada) was used to acquire RF data from 163 patients directly before 12-core biopsy (1,956 cores total). These retrospective data are a subset of data acquired in a multisite, 1,676-patient, randomized, clinical trial (clinicaltrials.gov NCT02079025). Machine learning-based lesion detection incorporated the following spectral-QUS features: effective scatter diameter (ESD), effective acoustic concentration (EAC), midband (M), intercept (I) and slope (S) as well as envelope statistics using a Nakagami distribution. The values of these features were calculated and used to train linear discriminant classifiers (LDCs) and support-vector machines (SVMs). Classifier performance was assessed using area-under-the-curve (AUC) values obtained from receiver operating characteristic (ROC) analyses with 10-fold cross validation. RESULTS: A combination of ESD and EAC parameters resulted in an AUC value of 0.75 using an LDC. When the PSA value was added as a feature, the AUC increased to 0.79. The best classification performance was obtained using an LDC by combining envelope statistics, PSA, ESD and EAC, which resulted in an AUC of 0.81. Using an SVM did not improve the classification significantly (i.e., best classifier AUC~0.75). In a separate study of the imaging capabilities of the ExactVuTM instrument, B-mode-based scoring and evaluation of lesions achieved an AUC of 0.74 for higher GS values (Gleason Sum > 7) for images interpreted by an expert. CONCLUSIONS: The AUC value of 0.81 achieved in the current study provides an encouraging basis for developing a new, entirely objective, automated method of assessing prostate-cancer risk and depicting suspicious regions in fine-resolution, real-time, micro-ultrasound images. The study results demonstrate that QUS-based imaging methods have great promise for reliably targeting prostate biopsies, planning and delivering focal treatment of prostate cancers, and monitoring treated or watched prostate cancers. | F11: J. Urol. | G11: JOUR; Conference Abstract | H11: YES | I11: EXCLUDE | J11: Ineligible publication type | K11: CONFERENCE_ABSTRACT | L11: 46313 | M11: =IF(OR(I11="INCLUDE",I11="UNCERTAIN"),"RETRIEVE",IF(I11="EXCLUDE","EXCLUDE",""))
A12: 9 | B12: LIB-06190 | C12: 2025 | D12: Artificial Intelligence Across the Prostate Cancer Pathway: Screening, Imaging, Pathology, and Biomarkers. | E12: Artificial intelligence (AI) has made great changes to prostate cancer screening and early detection across biomarkers, imaging, and pathology. On micro-ultrasound (micro-US), AI improves discrimination and raises specificity at comparable sensitivity versus clinical models, while multimodal magnetic resonance imaging-transrectal US (MRI-TRUS) AI achieves higher specificity at matched sensitivity. Liquid-biopsy programs combine fragmentomics with ctDNA and cell-free mRNA interpreted by AI, enabling noninvasive risk stratification and clinical feasibility. In imaging, AI for MRI matches or exceeds expert radiologists in large reader studies and MRI benchmarks; commercial tools show robust patient- and lesion-level performance. Quantitative pipelines (e.g., automated tissue-composition metrics) aid equivocal Prostate Imaging-Reporting and Data System (PI-RADS 3) lesions with PSA density, and AI-derived intraprostatic tumor volume offers independent prognostic value. Multimodal fusion of MRI with TRUS boosts detection, and automated prostate-specific membrane antigen (PSMA) PET/CT algorithms quantify tumor burden and support longitudinal response tracking. In pathology, clinical-grade AI automates cancer detection and Gleason grading, cutting reading time, ancillary tests, and second-opinion requests, while supporting integrative prognostic models. Downstream, AI accelerates radiotherapy planning, guides focal therapies and surgical margins, personalizes systemic therapy, and enables early post-treatment monitoring. Translation still requires rigorous, prospective, multi-site validation. | F12: Cureus | G12: Journal Article; Review | H12: YES | I12: EXCLUDE | J12: Ineligible publication type | K12: NON_PRIMARY_PUBLICATION | L12: 46313 | M12: =IF(OR(I12="INCLUDE",I12="UNCERTAIN"),"RETRIEVE",IF(I12="EXCLUDE","EXCLUDE",""))
A13: 10 | B13: LIB-00667 | C13: 2020 | D13: Validation and implementation of a mobile app decision support system for quality assurance of tumor boards. Analyzing the concordance rates for prostate cancer at a multidisciplinary tumor board of a tertiary referral centre | E13: Introduction & Objectives: Certified Cancer Centers are instructed to present 100% of all cases at multidisciplinary tumor boards (MTD). Discussion of standard cases limits the time of more demanding cases. A validated expert-curated decision support system (DSS) could avoid the discussion of standard cases in MTD and provide sufficient time for demanding cases. Materials & Methods: In order to verify the quality of each single tumor board decision, we first developed a partially algorithm-driven DSS mobile application to provide evidence-based recommendations for first-line therapy of common urological cancers. In a second step, concordance rate was determined by comparing treatment recommendations given by DSS and MTD. Data of 1924 patients with prostate cancer being discussed in the MTD of the urological department of the University Hospital of Cologne between 2014 and 2018 have been included for evaluation. Patient characteristics included age, disease stage, Gleason Score, PSA and previous therapies. All cases were then answered using the DSS mobile application. The results of both MTD and DSS were included into an identical layout style for reviewer evaluation. All pairs of answers were compared by two independent, blinded reviewers and were categorized into four groups of concordance level: Identical decision (ID), correct alternative decision (CAD), different decision (DD), no decision (ND). Results: Overall concordance rate was 99.6%, including 94.1% ID and 5.5% CAD. Stage specific concordance rates were 99.6% (stage I), 99.8% (stage II), 100% (stage III), and 99.3% (stage IV). Quality of concordance were independent of age, risk profile or line of treatment. Conclusions: Our expert-curated DSS provides nearly 100% concordance with a specialized MTD. Despite these good results and superiority to other DSS reported so far, we aim for a next generation solution with mutual quality control on both sides: human being and machine and vice versa. To assure quality and to fulfill the expectation to become a standard tool for validation and quality assurance of multidisciplinary tumor boards in general, we currently initiate a prospective multicenter board cross-validation trial. | F13: Eu. Uro. Op. Sci | G13: JOUR; Conference Abstract | H13: YES | I13: EXCLUDE | J13: Ineligible publication type | K13: CONFERENCE_ABSTRACT | L13: 46313 | M13: =IF(OR(I13="INCLUDE",I13="UNCERTAIN"),"RETRIEVE",IF(I13="EXCLUDE","EXCLUDE",""))
A14: 11 | B14: LIB-04638 | C14: 2019 | D14: Prediction of metastatic castrate-resistant prostate cancer response to abiraterone or enzalutamide by a baseline blood-based CTC gene expression signature | E14: Background: Prostate cancer is the most common cancer in men in the U.S., with 30% 5-year overall survival (OS) for patients (pts) with metastases. To take a precision medicine approach to the management of metastatic castrate-resistant prostate cancer (mCRPC), we developed a blood circulating tumor cell (CTC)-based test to identify mCRPC pts most likely to benefit from abiraterone (abi) or enzalutamide (enza). Methods: In this multi-institution prospective study, men with mCRPC were enrolled prior to starting abi (1,000 mg/d plus prednisone 10 mg/d) or enza (160 mg/d). At baseline (BL), 12 w, and progression, blood samples were collected for CellSearch-based CTC enumeration and qPCR-based gene expression analysis. Results: 69 pts (median age 68 y [50-82]) received abi (n = 25) or enza (n = 44) and had evaluable blood samples. Consistent with prior publications, among 43 pts with BL CTC > 0, clearance of detectable CTCs (BL CTCs > 0 and 12 w CTCs = 0), was achieved in 24 patients (55.8%), and was associated with greater median OS (31 mo vs. 18 mo, log-rank p = 0.03). The 43 pts with BL CTC > 0 were then randomly divided into training (n = 31) and validation (n = 12) sets. Baseline gene expression data for the training set was used to develop a model to predict CTC clearance, starting with a panel of 141 expressed genes/isoforms including those associated with prostate cancer. Of the models tested, random forest yielded the best performance, with respective training and validation set sensitivity of 0.7 and 1, specificity 0.75 and 0.71, AUC 0.88 and 0.91. Top genes identified include those previously associated with disease - HOXB13, ESRP2, KLK3, GRHL2, andKRT19, among others. Conclusions: A gene expression signature from a baseline blood sample with CellSearch-enriched CTCs can predict clearance of detectable CTCs in response to abi/enza with high AUC and may give insight into molecular mechanisms of response. A prospective study with a larger number of patients will be required to further validate our findings. Ultimately, this blood test has the potential to select the patients most likely to benefit from second-generation antiandrogen vs. non-hormonal systemic treatment. | F14: J. Clin. Oncol. | G14: JOUR; Conference Abstract | H14: YES | I14: EXCLUDE | J14: Ineligible publication type | K14: CONFERENCE_ABSTRACT | L14: 46313 | M14: =IF(OR(I14="INCLUDE",I14="UNCERTAIN"),"RETRIEVE",IF(I14="EXCLUDE","EXCLUDE",""))
A15: 12 | B15: LIB-02978 | C15: 2025 | D15: AI-driven and Traditional Radiomic Model for Predicting Muscle Invasion in Bladder Cancer via Multi-parametric Imaging: A Systematic Review and Meta-analysis. | E15: RATIONALE AND OBJECTIVES: This study systematically evaluates the diagnostic performance of artificial intelligence (AI)-driven and conventional radiomics models in detecting muscle-invasive bladder cancer (MIBC) through meta-analytical approaches. Furthermore, it investigates their potential synergistic value with the Vesical Imaging-Reporting and Data System (VI-RADS) and assesses clinical translation prospects. METHODS: This study adhered to the Preferred Reporting Items for Systematic Reviews and Meta-Analyses (PRISMA) guidelines. We conducted a comprehensive systematic search of PubMed, Web of Science, Embase, and Cochrane Library databases up to May 13, 2025, and manually screened the references of included studies. The quality and risk of bias of the selected studies were assessed using the Quality Assessment of Diagnostic Accuracy Studies 2 (QUADAS-2) and Radiomics Quality Score (RQS) tools. We pooled the area under the curve (AUC), sensitivity, specificity, positive likelihood ratio (PLR), negative likelihood ratio (NLR), diagnostic odds ratio (DOR), and their 95% confidence intervals (95% CI). Additionally, meta-regression and subgroup analyses were performed to identify potential sources of heterogeneity. RESULTS: This meta-analysis incorporated 43 studies comprising 9624 patients. The majority of included studies demonstrated low risk of bias, with a mean RQS of 18.89. Pooled analysis yielded an AUC of 0.92 (95% CI: 0.89-0.94). The aggregate sensitivity and specificity were both 0.86 (95% CI: 0.84-0.87), with heterogeneity indices of I² = 43.58 and I² = 72.76, respectively. The PLR was 5.97 (95% CI: 5.28-6.75, I² = 64.04), while the NLR was 0.17 (95% CI: 0.15-0.19, I² = 37.68). The DOR reached 35.57 (95% CI: 29.76-42.51, I² = 99.92). Notably, all included studies exhibited significant heterogeneity (P < 0.1). Meta-regression and subgroup analyses identified several significant sources of heterogeneity, including: study center type (single-center vs. multi-center), sample size (<100 vs. ≥100 patients), dataset classification (training, validation, testing, or ungrouped), imaging modality (computed tomography [CT] vs. magnetic resonance imaging [MRI]), modeling algorithm (deep learning vs. machine learning vs. other), validation methodology (cross-validation vs. cohort validation), segmentation method (manual vs. [semi]automated), regional differences (China vs. other countries), and risk of bias (high vs. low vs. unclear). CONCLUSION: AI-driven and traditional radiomic models have exhibited robust diagnostic performance for MIBC. Nevertheless, substantial heterogeneity across studies necessitates validation through multinational, multicenter prospective cohort studies to establish external validity. | F15: Academic radiology | G15: Journal Article; Meta-Analysis; Systematic Review; Research Support, Non-U.S. Gov't | H15: YES | I15: EXCLUDE | J15: Ineligible publication type | K15: NON_PRIMARY_PUBLICATION | L15: 46313 | M15: =IF(OR(I15="INCLUDE",I15="UNCERTAIN"),"RETRIEVE",IF(I15="EXCLUDE","EXCLUDE",""))
... A48: 45 | B48: LIB-05847 | C48: 2026 | D48: Online adaptive radiotherapy in pelvic and thoracic cancers - comparing toxicities, clinical outcomes and technical parameters between conventional image-guided radiotherapy and online adaptive radiotherapy - the study protocol for the prospective, registry-based cohort study (PRoART). | E48: BACKGROUND: Conventional image-guided radiotherapy (IGRT) typically relies on a computed tomography (CT)-based treatment planning process (planning CT, pCT) performed prior to the start of treatment. During this process, a patient-specific treatment plan is generated, which is then delivered to the patient with a linear accelerator on a daily basis, usually with image guidance to compensate for variations in patient setup. However, daily interfractional anatomical variations in target position, shape, and volume, as well as in surrounding organs at risk (OARs), can only be addressed indirectly by adding safety margins, resulting in larger irradiated volumes and potentially increased toxicity. Online adaptive radiotherapy (oART) is a promising and innovative technique to reduce such margins and, consequently, treatment-related toxicity. It uses daily imaging to generate a "plan of the day" that is aligned with the current patient anatomy, often supported by artificial intelligence (AI), while the patient remains on the treatment couch. Through daily image-guided re-optimization of the radiation treatment (RT) plan on the anatomy of the day, target coverage may also be improved. This approach is particularly attractive in the pelvic region, where high interfractional anatomical variability, for example due to peristalsis or changes in bladder and rectal filling, is frequently observed. METHODS: This prospective registry-based cohort study will include patients with pelvic or thoracic tumors with an indication for RT treated with IGRT or oART using the Varian Ethos™ system. The primary endpoint is defined as a 10% reduction in the rate of acute RT related toxicity (≥Common Terminology Criteria for Adverse Events (CTCAE) II°, v5.0) using oART. Secondary endpoints encompass clinical outcomes including late toxicities, tumor control rates, and patient-reported outcomes (PROs), as well as technical factors such as target volume, coverage, dose to OARs and anatomical variability score. While the cohort study compares IGRT versus oART for primary and secondary clinical endpoints, it also evaluates the real oART scenario against two hypothetical control scenarios for technical endpoints. DISCUSSION: The introduction of oART promises a reduction in toxicities and improved target volume coverage, potentially resulting in enhanced tumor control rates. It is poised to be a pioneering technology in the field of radiation oncology. Given the absence of a direct comparison between IGRT and oART thus far, the prospective registry-based cohort study PRoART aims to address this gap. TRIAL REGISTRATION: Clinical trial number NCT06185062, Clinicaltrials.gov. Registered 12/14/2023. Last update 07/29/2026. | F48: BMC medical imaging | G48: Journal Article; Comparative Study | H48: YES | I48: EXCLUDE | J48: Protocol/no results | K48: PROTOCOL_NO_RESULTS | L48: 46313 | M48: =IF(OR(I48="INCLUDE",I48="UNCERTAIN"),"RETRIEVE",IF(I48="EXCLUDE","EXCLUDE",""))
A49: 46 | B49: LIB-01333 | C49: 2023 | D49: Thin-Slice Prostate MRI Enabled by Deep Learning Image Reconstruction. | E49: OBJECTIVES: Thin-slice prostate MRI might be beneficial for prostate cancer diagnostics. However, prolongation of acquisition time is a major drawback of thin-slice imaging. Therefore, the purpose of this study was to investigate the impact of a thin-slice deep learning accelerated T2-weighted (w) TSE imaging sequence (T2DLR) of the prostate as compared to conventional T2w TSE imaging (T2S). MATERIALS AND METHODS: Thirty patients were included in this prospective study at one university center after obtaining written informed consent. T2S (3 mm slice thickness) was acquired first in three orthogonal planes followed by thin-slice T2DLR (2 mm slice thickness) in axial plane. Acquisition time of axial conventional T2S was 4:12 min compared to 4:37 min for T2DLR. Imaging datasets were evaluated by two radiologists using a Likert-scale ranging from 1-4, with 4 being the best regarding the following parameters: sharpness, lesion detectability, artifacts, overall image quality, and diagnostic confidence. Furthermore, preference of T2S versus T2DLR was evaluated. RESULTS: The mean patient age was 68 ± 8 years. Sharpness of images and lesion detectability were rated better in T2DLR with a median of 4 versus a median of 3 in T2S (p < 0.001 for both readers). Image noise was evaluated to be significantly worse in T2DLR as compared to T2S (p < 0.001 and p = 0.021, respectively). Overall image quality was also evaluated to be superior in T2DLR versus T2S with a median of 4 versus 3 (p < 0.001 for both readers). Both readers chose T2DLR in 29 cases as their preference. CONCLUSIONS: Thin-slice T2DLR of the prostate provides a significant improvement of image quality without significant prolongation of acquisition time. | F49: Cancers | G49: Journal Article | H49: YES | I49: UNCERTAIN | K49: DL reconstruction prostate MRI, prospective; lesion detectability rated - check downstream task | L49: 46313 | M49: =IF(OR(I49="INCLUDE",I49="UNCERTAIN"),"RETRIEVE",IF(I49="EXCLUDE","EXCLUDE",""))
A50: 47 | B50: LIB-05128 | C50: 2023 | D50: DEEP LEARNING AUGMENTED DETECTION OF FLAT LESIONSON WHITE LIGHT CYSTOSCOPY | E50: INTRODUCTION AND OBJECTIVE: While-light cystoscopy (WLC) has inadequate performance for detection of flat lesions such as carcinoma in situ. Blue-light cystoscopy (BLC) has improved flat-lesion detection, however adoption is modest due to equipment cost, drug instillation, and user experience. Here we develop a non-invasive, deep learning-based algorithm to augment WLC flat lesion detection by using blue-light informed transfer learning. METHODS: CystoFlatNet was developed based on CystoNet, a deep learning platform for WLC bladder cancer detection. CystoNet was enhanced to augment flat lesion detection in two stages. First, a WLC image was input into a BLC domain using domain adaption of Cycle- GAN. Second, a region of interest (ROI) detector was used to segment the regions within the transferred images occupied by a flat lesion. Transfer learning was applied to embed features learned from both WLC and BLC into the model weights. Algorithm outputs included an outline deployed in WLC and a “mock” BLC output. For algorithm development, images of WLC and BLC matches from 50 subjects with flat lesions were selected and annotated. A training set consisting of 40 subjects and a test set of 10 subjects were used. Training was performed on WLC and BLC images. WLC was the only input used for validation. Per-lesion sensitivity was determined and performance compared to CystoNet. RESULTS: CystoFlatNet detected flat lesions on WLC with a 90% per-lesion sensitivity (9/10). In comparison, the previously trained CystoNet had a 30% per-lesion sensitivity (3/10). Large accuracy gains were obtained in ROI overlap and visual guidance in the blue-light domain (Figure 1). CONCLUSIONS: We have developed a deep-learning algorithm that shows promise in WLC flat lesion detection. CystoFlatNet may aid in diagnostic decision-making and could serve as a non-invasive, accessible alternative to available adjunct technologies. Validation in a large prospective cohort is needed to further evaluate CystoFlatNet performance. (Figure Presented). | F50: J. Urol. | G50: JOUR; Conference Abstract | H50: YES | I50: EXCLUDE | J50: Ineligible publication type | K50: CONFERENCE_ABSTRACT | L50: 46313 | M50: =IF(OR(I50="INCLUDE",I50="UNCERTAIN"),"RETRIEVE",IF(I50="EXCLUDE","EXCLUDE",""))
A51: 48 | B51: LIB-04332 | C51: 2016 | D51: Clinical and genomic characterization of metastatic small cell/neuroendocrine prostate cancer (SCNC) and intermediate atypical prostate cancer (IAC): Results from the SU2C/PCF/AACRWest Coast Prostate Cancer Dream Team (WCDT) | E51: Background: SCNC and a novel pathologic subtype, IAC, comprise a growing proportion of mCRPC patients resistant to androgen signaling inhibitors such as Abiraterone (Abi) or Enzalutamide (Enz). We sought to characterize these nonadenocarcinoma (adeno) subtypes in a prospective biopsy study. Methods: Eligible mCRPC pts underwent a metastasis biopsy (bx), and were followed for clinical outcomes. Tissue was both frozen and formalin fixed/paraffin embedded (FFPE). Independent review of FFPE specimens was undertaken by 3 pathologists. Frozen specimens underwent laser capture microdissection prior to RNA sequencing (seq). Machine learning was used to derive histologyspecific expression signatures. Signature accuracy was evaluated with leavepairout crossvalidation and application to an independent data set. Results: 226 of 300 planned mCRPC pts (74% resistant to Abi and/or Enz) have undergone bx (including 123 bone, 61 node, and 23 liver bx) with a 78% evaluable biopsy rate. Adeno was identified in 39%, nonadeno in 41% (SCNC in 12%, IAC in 29%), with other mixtures in the remaining 20%. Median overall survival (OS) from time of biopsy for pts with nonadeno histologies was 12.8 months (mos) [ IAC OS = 19.1 mos; SCNC OS = 12.8 mos] versus 25.8 mos in adeno pts (p=0.023). RNAseq data are available from 94 bx. Transcriptional signatures were developed which accurately distinguish adeno, SCNC and IAC. IAC appears to have a signature intermediate between adeno and SCNC. When applied to an independent data set (Beltran et al, Ca Disc 2011), these transcriptional signatures identified SCNC with 100% accuracy, and predict for IAC differentiation in a subset of nonSCNC tumors. Conclusions: A majority of CRPC metastases exhibit nonadenocarcinoma features, which are associated with a shortened survival. IAC and SCNC are genomically distinct, and newly derived transcriptional signatures based on these bx can be used to identify SCNC in an independent data set. Integration of whole exome with RNAseq data are ongoing to identify pathways upregulated in IAC and SCNC. | F51: J. Clin. Oncol. | G51: JOUR; Conference Abstract | H51: YES | I51: EXCLUDE | J51: Ineligible publication type | K51: CONFERENCE_ABSTRACT | L51: 46313 | M51: =IF(OR(I51="INCLUDE",I51="UNCERTAIN"),"RETRIEVE",IF(I51="EXCLUDE","EXCLUDE",""))
A52: 49 | B52: LIB-00529 | C52: 2019 | D52: 2019 Research Workshop: Treatment of Oligometastatic Disease - Closer to the Cure | E52: The proceedings contains 18 papers. The topics discussed include: Plasma Circulating Tumor HPV DNA for Early Detection of Cancer Recurrence in HPV-associated Oropharyngeal Cancer;A Validated Radiomics T Cell Score Predicts Response to Multi-site SBRT Combined with Pembrolizumab;Dosimetric Comparison of Biologically-Guided Radiotherapy and X-ray-Guided Stereotactic Ablative Radiotherapy for Oligometastatic Prostate Cancer;Multi-Site SBRT and Sequential Pembrolizumab: Treated Metastasis Control and Immune-Related Expression Predict Outcomes;Phase 1b study of stereotactic body radiation therapy in combination with systemic therapy in patients with extracranial oligometastatic renal cell carcinoma;Management of Oligometastatic Squamous Cell Carcinoma of the Head and Neck;Number of Metastatic Organ Sites and Survival by Molecular Profile in Lung Adenocarcinoma;Stereotactic Ablative Radiation Therapy for Oligometastatic Non-Small Cell Lung Cancer, Subset Analysis of a Prospective Phase II Clinical Trial;Increased Biologically Effective Dose (BED) To The Primary Tumor Improves Survival in Patients with Oligometastatic NSCLC: A Retrospective Dose Response Analysis;Radium 223 Dichloride in Combination with Androgen Deprivation Therapy and Stereotactic Body Radiation Therapy for Patients with Stage IV Oligometastatic Castration Sensitive Prostate Cancer: Clinical Trial in Progress;Platform Phase I Study Investigating the Safety of Multisite Stereotactic Body Radiotherapy with Immuno-Oncology Agents for the Treatment of Metastatic Advanced Solid Tumors;Radiotherapy In The Definitive Management Of Oligometastatic Prostate Cancer;Predictive factors and survival outcomes with stereotactic body radiation therapy in treatment of oligometastases in colorectal cancer;Long-term Disease Control and Survival Observed after Stereotactic Body Radiotherapy for Oligometastatic Breast Cancer;Molecular Profiling of Oligometastases and Artificial Intelligence-based Model for Predicting Treatment Outcome in Advance Prostate Cancer;Advance SBRT approaches for patients with oligometastases;Neoadjuvant Stereotactic Ablative and Hypofractionated Radiotherapy for Oligometastatic NSCLC | F52: Int. J. Radiat. Oncol. Biol. Phys. | G52: JOUR; Conference Review | H52: YES | I52: EXCLUDE | J52: Ineligible publication type | K52: CONFERENCE_ABSTRACT | L52: 46313 | M52: =IF(OR(I52="INCLUDE",I52="UNCERTAIN"),"RETRIEVE",IF(I52="EXCLUDE","EXCLUDE",""))
A53: 50 | B53: LIB-04530 | C53: 2018 | D53: Entering an era of radiogenomics in prostate cancer risk stratification. | E53: Radiogenomics is a field that amalgamates data from genomics and imaging techniques in order to derive clinically meaningful trends. In this article, we discuss the importance of prostate cancer risk classification and how data derived from genomic testing and multi-parametric magnetic resonance imaging (mpMRI) can be integrated into clinical decision-making processes with a focus on active surveillance (AS). Finally, we describe an ongoing prospective trial (Miami MAST trial) which incorporates imaging (mpMRI) and radiomics data in patients who are on AS for prostate cancer. | F53: Translational andrology and urology | G53: Journal Article; Review | H53: YES | I53: EXCLUDE | J53: Ineligible publication type | K53: NON_PRIMARY_PUBLICATION | L53: 46313 | M53: =IF(OR(I53="INCLUDE",I53="UNCERTAIN"),"RETRIEVE",IF(I53="EXCLUDE","EXCLUDE",""))
A54: 51 | B54: LIB-03540 | C54: 2026 | D54: Development and validation of a risk prediction model for chemical cystitis in patients with non-muscle-invasive bladder cancer undergoing intravesical instillation | E54: Objective: To develop and validate a risk prediction model for Chemical cystitis in patients with non-muscle-invasive bladder cancer (NMIBC) undergoing intravesical instillation. Methods: This study retrospectively enrolled 225 patients with NMIBC who received intravesical instillation between January 2024 and January 2026. Predictive variables, including demographic characteristics, oncological features, medical history, treatment-related factors, and procedural anatomy, were collected. Feature selection was performed using the Least Absolute Shrinkage and Selection Operator (LASSO) regression from 18 candidate variables. A multivariable logistic regression model was constructed based on the selected variables and visualized as a risk prediction nomogram. The model’s performance was evaluated and validated using the Area Under the Curve (AUC), calibration curves, and Decision Curve Analysis (DCA) to assess discrimination, calibration, and clinical utility. Results: Five independent predictors were identified from the candidate variables through LASSO and multivariable logistic regression analysis: type of instillation agent, tumor multifocality, retention time of the agent, bladder capacity, and tumor grade. The predictive model demonstrated robust discriminative ability in both the training and validation cohorts, with AUC values of 0.840 and 0.868, respectively. Calibration curves showed high consistency between the predicted and observed risks, and DCA further confirmed the model’s positive net benefit in clinical decision-making. Conclusion: We successfully developed and validated a practical nomogram for the individualized prediction of Chemical cystitis risk in patients with NMIBC. This tool can assist clinicians in identifying high-risk patients prior to treatment, thereby enabling more targeted monitoring and preventive strategies. This study is limited by its single-center retrospective design, and external prospective validation is warranted. | F54: Oncol. Rev. | G54: JOUR; Article | H54: YES | I54: EXCLUDE | J54: Retrospective-only/ineligible design | K54: RETROSPECTIVE_ONLY | L54: 46313 | M54: =IF(OR(I54="INCLUDE",I54="UNCERTAIN"),"RETRIEVE",IF(I54="EXCLUDE","EXCLUDE",""))
A55: 52 | B55: LIB-00451 | C55: 2026 | D55: Prostate MRI Analysis by Radiologists and Artificial Intelligence - Disease Identification and Guided Management | E55: Aim: To assess whether artificial intelligence is non‐inferior to radiologists in thediagnosis of clinically significant prostate cancer on MRI.ObjectivesPrimary1. To compare the proportion of men who have clinically significant prostate cancerdetected on MRI using AI ± targeted biopsy with radiologists ± targeted biopsy.Secondary 1. To compare the proportion of men who have clinically insignificant prostate cancerdetected on MRI using AI ± targeted biopsy with radiologists ± targeted biopsy. 2. To compare the proportion of men with non‐suspicious MRIs for AI vs radiologists. 3. To compare the proportion of men with indeterminately scored MRI as reported by AIvs radiologists. 4. To compare the diagnostic test performance of AI vs radiologist. 5. To compare the additive value of AI when used together with a radiologistinterpretation (summative of all identified lesions) compared to a radiologistalone. 6. To compare the additive value of AI when used together with a radiologistinterpretation (where the radiologist can interact with the AI system by acceptingor rejecting AI‐identified lesions) compared to a radiologist alone. 7. To determine the frequency of AI failures. 8. To compare treatment eligibility decisions between AI and Radiologist. 9. To compare the cost‐effectiveness of unblinded AI interpreted by the radiologistcompared to radiologist alone for prostate cancer detection, and AI alone vs.radiologist alone, and a 3‐arm analysis considering all three.Design:Prospective, international, within‐patient, multi‐centre, level‐1 evidence trial inparticipants referred to hospital with a clinical suspicion of prostate cancer. | F55: https://clinicaltrials.gov/study/NCT07647445 | G55: JOUR; Trial registry record | H55: YES | I55: EXCLUDE | J55: Protocol/no results | K55: PROTOCOL_NO_RESULTS | L55: 46313 | M55: =IF(OR(I55="INCLUDE",I55="UNCERTAIN"),"RETRIEVE",IF(I55="EXCLUDE","EXCLUDE",""))
